[2024-04-25T15:21:58.703+0000] {taskinstance.py:1159} INFO - Dependencies all met for dep_context=non-requeueable deps ti=<TaskInstance: etl_reddit_pipeline.s3_upload manual__2024-04-25T15:21:54.918110+00:00 [queued]>
[2024-04-25T15:21:58.708+0000] {taskinstance.py:1159} INFO - Dependencies all met for dep_context=requeueable deps ti=<TaskInstance: etl_reddit_pipeline.s3_upload manual__2024-04-25T15:21:54.918110+00:00 [queued]>
[2024-04-25T15:21:58.708+0000] {taskinstance.py:1361} INFO - Starting attempt 1 of 1
[2024-04-25T15:21:58.713+0000] {taskinstance.py:1382} INFO - Executing <Task(PythonOperator): s3_upload> on 2024-04-25 15:21:54.918110+00:00
[2024-04-25T15:21:58.718+0000] {standard_task_runner.py:57} INFO - Started process 68 to run task
[2024-04-25T15:21:58.720+0000] {standard_task_runner.py:84} INFO - Running: ['airflow', 'tasks', 'run', 'etl_reddit_pipeline', 's3_upload', 'manual__2024-04-25T15:21:54.918110+00:00', '--job-id', '8', '--raw', '--subdir', 'DAGS_FOLDER/reddit_dag.py', '--cfg-path', '/tmp/tmpfotksrro']
[2024-04-25T15:21:58.722+0000] {standard_task_runner.py:85} INFO - Job 8: Subtask s3_upload
[2024-04-25T15:21:58.745+0000] {task_command.py:416} INFO - Running <TaskInstance: etl_reddit_pipeline.s3_upload manual__2024-04-25T15:21:54.918110+00:00 [running]> on host 1bd1b115cb8b
[2024-04-25T15:21:58.773+0000] {taskinstance.py:1662} INFO - Exporting env vars: AIRFLOW_CTX_DAG_OWNER='Aida Sow' AIRFLOW_CTX_DAG_ID='etl_reddit_pipeline' AIRFLOW_CTX_TASK_ID='s3_upload' AIRFLOW_CTX_EXECUTION_DATE='2024-04-25T15:21:54.918110+00:00' AIRFLOW_CTX_TRY_NUMBER='1' AIRFLOW_CTX_DAG_RUN_ID='manual__2024-04-25T15:21:54.918110+00:00'
[2024-04-25T15:21:58.774+0000] {taskinstance.py:1937} ERROR - Task failed with exception
Traceback (most recent call last):
  File "/home/airflow/.local/lib/python3.9/site-packages/airflow/operators/python.py", line 192, in execute
    return_value = self.execute_callable()
  File "/home/airflow/.local/lib/python3.9/site-packages/airflow/operators/python.py", line 209, in execute_callable
    return self.python_callable(*self.op_args, **self.op_kwargs)
  File "/opt/airflow/pipelines/upload_s3_pipeline.py", line 7, in upload_s3_pipeline
    file_path= ti.xcom_pull(task_ids='reddit_extraction', keys='return_value')
  File "/home/airflow/.local/lib/python3.9/site-packages/airflow/utils/session.py", line 77, in wrapper
    return func(*args, session=session, **kwargs)
TypeError: xcom_pull() got an unexpected keyword argument 'keys'
[2024-04-25T15:21:58.778+0000] {taskinstance.py:1400} INFO - Marking task as FAILED. dag_id=etl_reddit_pipeline, task_id=s3_upload, execution_date=20240425T152154, start_date=20240425T152158, end_date=20240425T152158
[2024-04-25T15:21:58.787+0000] {standard_task_runner.py:104} ERROR - Failed to execute job 8 for task s3_upload (xcom_pull() got an unexpected keyword argument 'keys'; 68)
[2024-04-25T15:21:58.821+0000] {local_task_job_runner.py:228} INFO - Task exited with return code 1
[2024-04-25T15:21:58.830+0000] {taskinstance.py:2778} INFO - 0 downstream tasks scheduled from follow-on schedule check
